[2023-12-14T16:49:50.188+0000] {taskinstance.py:1159} INFO - Dependencies all met for dep_context=non-requeueable deps ti=<TaskInstance: daily_transaction_fact.update_transaction_fact manual__2023-12-14T16:43:59.453216+00:00 [queued]>
[2023-12-14T16:49:50.195+0000] {taskinstance.py:1159} INFO - Dependencies all met for dep_context=requeueable deps ti=<TaskInstance: daily_transaction_fact.update_transaction_fact manual__2023-12-14T16:43:59.453216+00:00 [queued]>
[2023-12-14T16:49:50.195+0000] {taskinstance.py:1361} INFO - Starting attempt 2 of 2
[2023-12-14T16:49:50.208+0000] {taskinstance.py:1382} INFO - Executing <Task(PythonOperator): update_transaction_fact> on 2023-12-14 16:43:59.453216+00:00
[2023-12-14T16:49:50.213+0000] {standard_task_runner.py:57} INFO - Started process 58 to run task
[2023-12-14T16:49:50.215+0000] {standard_task_runner.py:84} INFO - Running: ['***', 'tasks', 'run', 'daily_transaction_fact', 'update_transaction_fact', 'manual__2023-12-14T16:43:59.453216+00:00', '--job-id', '10', '--raw', '--subdir', 'DAGS_FOLDER/transaction_fact.py', '--cfg-path', '/tmp/tmp32jkvm2i']
[2023-12-14T16:49:50.217+0000] {standard_task_runner.py:85} INFO - Job 10: Subtask update_transaction_fact
[2023-12-14T16:49:50.255+0000] {task_command.py:416} INFO - Running <TaskInstance: daily_transaction_fact.update_transaction_fact manual__2023-12-14T16:43:59.453216+00:00 [running]> on host 052e9c2ae5ce
[2023-12-14T16:49:50.313+0000] {taskinstance.py:1662} INFO - Exporting env vars: AIRFLOW_CTX_DAG_OWNER='admin' AIRFLOW_CTX_DAG_ID='daily_transaction_fact' AIRFLOW_CTX_TASK_ID='update_transaction_fact' AIRFLOW_CTX_EXECUTION_DATE='2023-12-14T16:43:59.453216+00:00' AIRFLOW_CTX_TRY_NUMBER='2' AIRFLOW_CTX_DAG_RUN_ID='manual__2023-12-14T16:43:59.453216+00:00'
[2023-12-14T16:49:50.315+0000] {taskinstance.py:1937} ERROR - Task failed with exception
Traceback (most recent call last):
  File "/home/airflow/.local/lib/python3.8/site-packages/airflow/operators/python.py", line 192, in execute
    return_value = self.execute_callable()
  File "/home/airflow/.local/lib/python3.8/site-packages/airflow/operators/python.py", line 209, in execute_callable
    return self.python_callable(*self.op_args, **self.op_kwargs)
TypeError: update_transaction_fact() missing 1 required positional argument: 'records'
[2023-12-14T16:49:50.322+0000] {taskinstance.py:1400} INFO - Marking task as FAILED. dag_id=daily_transaction_fact, task_id=update_transaction_fact, execution_date=20231214T164359, start_date=20231214T164950, end_date=20231214T164950
[2023-12-14T16:49:50.333+0000] {standard_task_runner.py:104} ERROR - Failed to execute job 10 for task update_transaction_fact (update_transaction_fact() missing 1 required positional argument: 'records'; 58)
[2023-12-14T16:49:50.347+0000] {local_task_job_runner.py:228} INFO - Task exited with return code 1
[2023-12-14T16:49:50.362+0000] {taskinstance.py:2778} INFO - 0 downstream tasks scheduled from follow-on schedule check
