[2023-12-15T19:53:21.570+0000] {taskinstance.py:1159} INFO - Dependencies all met for dep_context=non-requeueable deps ti=<TaskInstance: daily_account_turnover.fetch_data_from_postgres scheduled__2023-12-14T00:00:00+00:00 [queued]>
[2023-12-15T19:53:21.576+0000] {taskinstance.py:1159} INFO - Dependencies all met for dep_context=requeueable deps ti=<TaskInstance: daily_account_turnover.fetch_data_from_postgres scheduled__2023-12-14T00:00:00+00:00 [queued]>
[2023-12-15T19:53:21.576+0000] {taskinstance.py:1361} INFO - Starting attempt 1 of 2
[2023-12-15T19:53:21.586+0000] {taskinstance.py:1382} INFO - Executing <Task(PythonOperator): fetch_data_from_postgres> on 2023-12-14 00:00:00+00:00
[2023-12-15T19:53:21.590+0000] {standard_task_runner.py:57} INFO - Started process 143 to run task
[2023-12-15T19:53:21.592+0000] {standard_task_runner.py:84} INFO - Running: ['***', 'tasks', 'run', 'daily_account_turnover', 'fetch_data_from_postgres', 'scheduled__2023-12-14T00:00:00+00:00', '--job-id', '3', '--raw', '--subdir', 'DAGS_FOLDER/account_turnover.py', '--cfg-path', '/tmp/tmp4e8mlo1w']
[2023-12-15T19:53:21.595+0000] {standard_task_runner.py:85} INFO - Job 3: Subtask fetch_data_from_postgres
[2023-12-15T19:53:21.637+0000] {task_command.py:416} INFO - Running <TaskInstance: daily_account_turnover.fetch_data_from_postgres scheduled__2023-12-14T00:00:00+00:00 [running]> on host e1cf21a7c005
[2023-12-15T19:53:21.712+0000] {taskinstance.py:1662} INFO - Exporting env vars: AIRFLOW_CTX_DAG_OWNER='***' AIRFLOW_CTX_DAG_ID='daily_account_turnover' AIRFLOW_CTX_TASK_ID='fetch_data_from_postgres' AIRFLOW_CTX_EXECUTION_DATE='2023-12-14T00:00:00+00:00' AIRFLOW_CTX_TRY_NUMBER='1' AIRFLOW_CTX_DAG_RUN_ID='scheduled__2023-12-14T00:00:00+00:00'
[2023-12-15T19:53:21.716+0000] {taskinstance.py:1937} ERROR - Task failed with exception
Traceback (most recent call last):
  File "/home/airflow/.local/lib/python3.8/site-packages/airflow/operators/python.py", line 192, in execute
    return_value = self.execute_callable()
  File "/home/airflow/.local/lib/python3.8/site-packages/airflow/operators/python.py", line 209, in execute_callable
    return self.python_callable(*self.op_args, **self.op_kwargs)
  File "/opt/airflow/dags/account_turnover.py", line 41, in fetch_data_from_postgres
    connection = psycopg2.connect(**connection)
TypeError: connect() argument after ** must be a mapping, not psycopg2.extensions.connection
[2023-12-15T19:53:21.725+0000] {taskinstance.py:1400} INFO - Marking task as UP_FOR_RETRY. dag_id=daily_account_turnover, task_id=fetch_data_from_postgres, execution_date=20231214T000000, start_date=20231215T195321, end_date=20231215T195321
[2023-12-15T19:53:21.741+0000] {standard_task_runner.py:104} ERROR - Failed to execute job 3 for task fetch_data_from_postgres (connect() argument after ** must be a mapping, not psycopg2.extensions.connection; 143)
[2023-12-15T19:53:21.764+0000] {local_task_job_runner.py:228} INFO - Task exited with return code 1
[2023-12-15T19:53:21.789+0000] {taskinstance.py:2778} INFO - 0 downstream tasks scheduled from follow-on schedule check
