[2023-12-14T16:50:11.425+0000] {taskinstance.py:1159} INFO - Dependencies all met for dep_context=non-requeueable deps ti=<TaskInstance: daily_turnover_per_account.fetch_data_from_postgres scheduled__2023-12-13T00:00:00+00:00 [queued]>
[2023-12-14T16:50:11.433+0000] {taskinstance.py:1159} INFO - Dependencies all met for dep_context=requeueable deps ti=<TaskInstance: daily_turnover_per_account.fetch_data_from_postgres scheduled__2023-12-13T00:00:00+00:00 [queued]>
[2023-12-14T16:50:11.433+0000] {taskinstance.py:1361} INFO - Starting attempt 2 of 2
[2023-12-14T16:50:11.444+0000] {taskinstance.py:1382} INFO - Executing <Task(PythonOperator): fetch_data_from_postgres> on 2023-12-13 00:00:00+00:00
[2023-12-14T16:50:11.452+0000] {standard_task_runner.py:57} INFO - Started process 73 to run task
[2023-12-14T16:50:11.454+0000] {standard_task_runner.py:84} INFO - Running: ['***', 'tasks', 'run', 'daily_turnover_per_account', 'fetch_data_from_postgres', 'scheduled__2023-12-13T00:00:00+00:00', '--job-id', '14', '--raw', '--subdir', 'DAGS_FOLDER/turnover_per_account.py', '--cfg-path', '/tmp/tmp9ojjk6fe']
[2023-12-14T16:50:11.456+0000] {standard_task_runner.py:85} INFO - Job 14: Subtask fetch_data_from_postgres
[2023-12-14T16:50:11.499+0000] {task_command.py:416} INFO - Running <TaskInstance: daily_turnover_per_account.fetch_data_from_postgres scheduled__2023-12-13T00:00:00+00:00 [running]> on host 052e9c2ae5ce
[2023-12-14T16:50:11.583+0000] {taskinstance.py:1662} INFO - Exporting env vars: AIRFLOW_CTX_DAG_OWNER='admin' AIRFLOW_CTX_DAG_ID='daily_turnover_per_account' AIRFLOW_CTX_TASK_ID='fetch_data_from_postgres' AIRFLOW_CTX_EXECUTION_DATE='2023-12-13T00:00:00+00:00' AIRFLOW_CTX_TRY_NUMBER='2' AIRFLOW_CTX_DAG_RUN_ID='scheduled__2023-12-13T00:00:00+00:00'
[2023-12-14T16:50:11.585+0000] {taskinstance.py:1937} ERROR - Task failed with exception
Traceback (most recent call last):
  File "/home/airflow/.local/lib/python3.8/site-packages/airflow/operators/python.py", line 192, in execute
    return_value = self.execute_callable()
  File "/home/airflow/.local/lib/python3.8/site-packages/airflow/operators/python.py", line 209, in execute_callable
    return self.python_callable(*self.op_args, **self.op_kwargs)
  File "/opt/airflow/dags/turnover_per_account.py", line 28, in fetch_data_from_postgres
    connection = psycopg2.connect(**postgres_conn_config)
  File "/home/airflow/.local/lib/python3.8/site-packages/psycopg2/__init__.py", line 122, in connect
    conn = _connect(dsn, connection_factory=connection_factory, **kwasync)
psycopg2.OperationalError: connection to server at "localhost" (127.0.0.1), port 5432 failed: Connection refused
	Is the server running on that host and accepting TCP/IP connections?
connection to server at "localhost" (::1), port 5432 failed: Cannot assign requested address
	Is the server running on that host and accepting TCP/IP connections?

[2023-12-14T16:50:11.594+0000] {taskinstance.py:1400} INFO - Marking task as FAILED. dag_id=daily_turnover_per_account, task_id=fetch_data_from_postgres, execution_date=20231213T000000, start_date=20231214T165011, end_date=20231214T165011
[2023-12-14T16:50:11.604+0000] {standard_task_runner.py:104} ERROR - Failed to execute job 14 for task fetch_data_from_postgres (connection to server at "localhost" (127.0.0.1), port 5432 failed: Connection refused
	Is the server running on that host and accepting TCP/IP connections?
connection to server at "localhost" (::1), port 5432 failed: Cannot assign requested address
	Is the server running on that host and accepting TCP/IP connections?
; 73)
[2023-12-14T16:50:11.626+0000] {local_task_job_runner.py:228} INFO - Task exited with return code 1
[2023-12-14T16:50:11.650+0000] {taskinstance.py:2778} INFO - 0 downstream tasks scheduled from follow-on schedule check
