[2023-12-15T18:34:01.355+0000] {taskinstance.py:1159} INFO - Dependencies all met for dep_context=non-requeueable deps ti=<TaskInstance: daily_turnover_per_account.update_turnover_per_account_type scheduled__2023-12-14T00:00:00+00:00 [queued]>
[2023-12-15T18:34:01.366+0000] {taskinstance.py:1159} INFO - Dependencies all met for dep_context=requeueable deps ti=<TaskInstance: daily_turnover_per_account.update_turnover_per_account_type scheduled__2023-12-14T00:00:00+00:00 [queued]>
[2023-12-15T18:34:01.366+0000] {taskinstance.py:1361} INFO - Starting attempt 1 of 2
[2023-12-15T18:34:01.380+0000] {taskinstance.py:1382} INFO - Executing <Task(PythonOperator): update_turnover_per_account_type> on 2023-12-14 00:00:00+00:00
[2023-12-15T18:34:01.390+0000] {standard_task_runner.py:57} INFO - Started process 132 to run task
[2023-12-15T18:34:01.392+0000] {standard_task_runner.py:84} INFO - Running: ['***', 'tasks', 'run', 'daily_turnover_per_account', 'update_turnover_per_account_type', 'scheduled__2023-12-14T00:00:00+00:00', '--job-id', '5', '--raw', '--subdir', 'DAGS_FOLDER/turnover_per_account.py', '--cfg-path', '/tmp/tmp_4byngdd']
[2023-12-15T18:34:01.395+0000] {standard_task_runner.py:85} INFO - Job 5: Subtask update_turnover_per_account_type
[2023-12-15T18:34:01.451+0000] {task_command.py:416} INFO - Running <TaskInstance: daily_turnover_per_account.update_turnover_per_account_type scheduled__2023-12-14T00:00:00+00:00 [running]> on host f4c0e6b5baef
[2023-12-15T18:34:01.537+0000] {taskinstance.py:1662} INFO - Exporting env vars: AIRFLOW_CTX_DAG_OWNER='admin' AIRFLOW_CTX_DAG_ID='daily_turnover_per_account' AIRFLOW_CTX_TASK_ID='update_turnover_per_account_type' AIRFLOW_CTX_EXECUTION_DATE='2023-12-14T00:00:00+00:00' AIRFLOW_CTX_TRY_NUMBER='1' AIRFLOW_CTX_DAG_RUN_ID='scheduled__2023-12-14T00:00:00+00:00'
[2023-12-15T18:34:01.539+0000] {taskinstance.py:1937} ERROR - Task failed with exception
Traceback (most recent call last):
  File "/home/airflow/.local/lib/python3.8/site-packages/airflow/operators/python.py", line 192, in execute
    return_value = self.execute_callable()
  File "/home/airflow/.local/lib/python3.8/site-packages/airflow/operators/python.py", line 209, in execute_callable
    return self.python_callable(*self.op_args, **self.op_kwargs)
  File "/opt/airflow/dags/turnover_per_account.py", line 79, in update_turnover_per_account_type
    connection = psycopg2.connect(**postgres_conn_config)
  File "/home/airflow/.local/lib/python3.8/site-packages/psycopg2/__init__.py", line 122, in connect
    conn = _connect(dsn, connection_factory=connection_factory, **kwasync)
psycopg2.OperationalError: connection to server at "localhost" (127.0.0.1), port 5432 failed: Connection refused
	Is the server running on that host and accepting TCP/IP connections?
connection to server at "localhost" (::1), port 5432 failed: Cannot assign requested address
	Is the server running on that host and accepting TCP/IP connections?

[2023-12-15T18:34:01.548+0000] {taskinstance.py:1400} INFO - Marking task as UP_FOR_RETRY. dag_id=daily_turnover_per_account, task_id=update_turnover_per_account_type, execution_date=20231214T000000, start_date=20231215T183401, end_date=20231215T183401
[2023-12-15T18:34:01.563+0000] {standard_task_runner.py:104} ERROR - Failed to execute job 5 for task update_turnover_per_account_type (connection to server at "localhost" (127.0.0.1), port 5432 failed: Connection refused
	Is the server running on that host and accepting TCP/IP connections?
connection to server at "localhost" (::1), port 5432 failed: Cannot assign requested address
	Is the server running on that host and accepting TCP/IP connections?
; 132)
[2023-12-15T18:34:01.604+0000] {local_task_job_runner.py:228} INFO - Task exited with return code 1
[2023-12-15T18:34:01.627+0000] {taskinstance.py:2778} INFO - 0 downstream tasks scheduled from follow-on schedule check
[2023-12-15T19:53:23.495+0000] {taskinstance.py:1159} INFO - Dependencies all met for dep_context=non-requeueable deps ti=<TaskInstance: daily_turnover_per_account.update_turnover_per_account_type scheduled__2023-12-14T00:00:00+00:00 [queued]>
[2023-12-15T19:53:23.503+0000] {taskinstance.py:1159} INFO - Dependencies all met for dep_context=requeueable deps ti=<TaskInstance: daily_turnover_per_account.update_turnover_per_account_type scheduled__2023-12-14T00:00:00+00:00 [queued]>
[2023-12-15T19:53:23.503+0000] {taskinstance.py:1361} INFO - Starting attempt 1 of 2
[2023-12-15T19:53:23.514+0000] {taskinstance.py:1382} INFO - Executing <Task(PythonOperator): update_turnover_per_account_type> on 2023-12-14 00:00:00+00:00
[2023-12-15T19:53:23.521+0000] {standard_task_runner.py:57} INFO - Started process 149 to run task
[2023-12-15T19:53:23.524+0000] {standard_task_runner.py:84} INFO - Running: ['***', 'tasks', 'run', 'daily_turnover_per_account', 'update_turnover_per_account_type', 'scheduled__2023-12-14T00:00:00+00:00', '--job-id', '6', '--raw', '--subdir', 'DAGS_FOLDER/turnover_per_account.py', '--cfg-path', '/tmp/tmprvflt81l']
[2023-12-15T19:53:23.526+0000] {standard_task_runner.py:85} INFO - Job 6: Subtask update_turnover_per_account_type
[2023-12-15T19:53:23.567+0000] {task_command.py:416} INFO - Running <TaskInstance: daily_turnover_per_account.update_turnover_per_account_type scheduled__2023-12-14T00:00:00+00:00 [running]> on host e1cf21a7c005
[2023-12-15T19:53:23.631+0000] {taskinstance.py:1662} INFO - Exporting env vars: AIRFLOW_CTX_DAG_OWNER='***' AIRFLOW_CTX_DAG_ID='daily_turnover_per_account' AIRFLOW_CTX_TASK_ID='update_turnover_per_account_type' AIRFLOW_CTX_EXECUTION_DATE='2023-12-14T00:00:00+00:00' AIRFLOW_CTX_TRY_NUMBER='1' AIRFLOW_CTX_DAG_RUN_ID='scheduled__2023-12-14T00:00:00+00:00'
[2023-12-15T19:53:23.634+0000] {python.py:194} INFO - Done. Returned value was: None
[2023-12-15T19:53:23.643+0000] {taskinstance.py:1400} INFO - Marking task as SUCCESS. dag_id=daily_turnover_per_account, task_id=update_turnover_per_account_type, execution_date=20231214T000000, start_date=20231215T195323, end_date=20231215T195323
[2023-12-15T19:53:23.696+0000] {local_task_job_runner.py:228} INFO - Task exited with return code 0
[2023-12-15T19:53:23.712+0000] {taskinstance.py:2778} INFO - 0 downstream tasks scheduled from follow-on schedule check
