[2023-12-14T16:49:50.192+0000] {taskinstance.py:1159} INFO - Dependencies all met for dep_context=non-requeueable deps ti=<TaskInstance: daily_transaction_fact.update_transaction_fact manual__2023-12-14T16:44:41.745540+00:00 [queued]>
[2023-12-14T16:49:50.200+0000] {taskinstance.py:1159} INFO - Dependencies all met for dep_context=requeueable deps ti=<TaskInstance: daily_transaction_fact.update_transaction_fact manual__2023-12-14T16:44:41.745540+00:00 [queued]>
[2023-12-14T16:49:50.200+0000] {taskinstance.py:1361} INFO - Starting attempt 2 of 2
[2023-12-14T16:49:50.212+0000] {taskinstance.py:1382} INFO - Executing <Task(PythonOperator): update_transaction_fact> on 2023-12-14 16:44:41.745540+00:00
[2023-12-14T16:49:50.218+0000] {standard_task_runner.py:57} INFO - Started process 59 to run task
[2023-12-14T16:49:50.220+0000] {standard_task_runner.py:84} INFO - Running: ['***', 'tasks', 'run', 'daily_transaction_fact', 'update_transaction_fact', 'manual__2023-12-14T16:44:41.745540+00:00', '--job-id', '12', '--raw', '--subdir', 'DAGS_FOLDER/transaction_fact.py', '--cfg-path', '/tmp/tmpr9r927ku']
[2023-12-14T16:49:50.222+0000] {standard_task_runner.py:85} INFO - Job 12: Subtask update_transaction_fact
[2023-12-14T16:49:50.261+0000] {task_command.py:416} INFO - Running <TaskInstance: daily_transaction_fact.update_transaction_fact manual__2023-12-14T16:44:41.745540+00:00 [running]> on host 052e9c2ae5ce
[2023-12-14T16:49:50.318+0000] {taskinstance.py:1662} INFO - Exporting env vars: AIRFLOW_CTX_DAG_OWNER='admin' AIRFLOW_CTX_DAG_ID='daily_transaction_fact' AIRFLOW_CTX_TASK_ID='update_transaction_fact' AIRFLOW_CTX_EXECUTION_DATE='2023-12-14T16:44:41.745540+00:00' AIRFLOW_CTX_TRY_NUMBER='2' AIRFLOW_CTX_DAG_RUN_ID='manual__2023-12-14T16:44:41.745540+00:00'
[2023-12-14T16:49:50.320+0000] {taskinstance.py:1937} ERROR - Task failed with exception
Traceback (most recent call last):
  File "/home/airflow/.local/lib/python3.8/site-packages/airflow/operators/python.py", line 192, in execute
    return_value = self.execute_callable()
  File "/home/airflow/.local/lib/python3.8/site-packages/airflow/operators/python.py", line 209, in execute_callable
    return self.python_callable(*self.op_args, **self.op_kwargs)
TypeError: update_transaction_fact() missing 1 required positional argument: 'records'
[2023-12-14T16:49:50.327+0000] {taskinstance.py:1400} INFO - Marking task as FAILED. dag_id=daily_transaction_fact, task_id=update_transaction_fact, execution_date=20231214T164441, start_date=20231214T164950, end_date=20231214T164950
[2023-12-14T16:49:50.336+0000] {standard_task_runner.py:104} ERROR - Failed to execute job 12 for task update_transaction_fact (update_transaction_fact() missing 1 required positional argument: 'records'; 59)
[2023-12-14T16:49:50.352+0000] {local_task_job_runner.py:228} INFO - Task exited with return code 1
[2023-12-14T16:49:50.367+0000] {taskinstance.py:2778} INFO - 0 downstream tasks scheduled from follow-on schedule check
