[2023-12-14T16:43:51.927+0000] {taskinstance.py:1159} INFO - Dependencies all met for dep_context=non-requeueable deps ti=<TaskInstance: daily_transaction_fact.update_transaction_fact scheduled__2023-12-13T00:00:00+00:00 [queued]>
[2023-12-14T16:43:51.933+0000] {taskinstance.py:1159} INFO - Dependencies all met for dep_context=requeueable deps ti=<TaskInstance: daily_transaction_fact.update_transaction_fact scheduled__2023-12-13T00:00:00+00:00 [queued]>
[2023-12-14T16:43:51.933+0000] {taskinstance.py:1361} INFO - Starting attempt 1 of 2
[2023-12-14T16:43:51.943+0000] {taskinstance.py:1382} INFO - Executing <Task(PythonOperator): update_transaction_fact> on 2023-12-13 00:00:00+00:00
[2023-12-14T16:43:51.948+0000] {standard_task_runner.py:57} INFO - Started process 78 to run task
[2023-12-14T16:43:51.950+0000] {standard_task_runner.py:84} INFO - Running: ['***', 'tasks', 'run', 'daily_transaction_fact', 'update_transaction_fact', 'scheduled__2023-12-13T00:00:00+00:00', '--job-id', '3', '--raw', '--subdir', 'DAGS_FOLDER/transaction_fact.py', '--cfg-path', '/tmp/tmpqe39zpbe']
[2023-12-14T16:43:51.952+0000] {standard_task_runner.py:85} INFO - Job 3: Subtask update_transaction_fact
[2023-12-14T16:43:51.990+0000] {task_command.py:416} INFO - Running <TaskInstance: daily_transaction_fact.update_transaction_fact scheduled__2023-12-13T00:00:00+00:00 [running]> on host 052e9c2ae5ce
[2023-12-14T16:43:52.078+0000] {taskinstance.py:1662} INFO - Exporting env vars: AIRFLOW_CTX_DAG_OWNER='admin' AIRFLOW_CTX_DAG_ID='daily_transaction_fact' AIRFLOW_CTX_TASK_ID='update_transaction_fact' AIRFLOW_CTX_EXECUTION_DATE='2023-12-13T00:00:00+00:00' AIRFLOW_CTX_TRY_NUMBER='1' AIRFLOW_CTX_DAG_RUN_ID='scheduled__2023-12-13T00:00:00+00:00'
[2023-12-14T16:43:52.080+0000] {taskinstance.py:1937} ERROR - Task failed with exception
Traceback (most recent call last):
  File "/home/airflow/.local/lib/python3.8/site-packages/airflow/operators/python.py", line 192, in execute
    return_value = self.execute_callable()
  File "/home/airflow/.local/lib/python3.8/site-packages/airflow/operators/python.py", line 209, in execute_callable
    return self.python_callable(*self.op_args, **self.op_kwargs)
TypeError: update_transaction_fact() missing 1 required positional argument: 'records'
[2023-12-14T16:43:52.093+0000] {taskinstance.py:1400} INFO - Marking task as UP_FOR_RETRY. dag_id=daily_transaction_fact, task_id=update_transaction_fact, execution_date=20231213T000000, start_date=20231214T164351, end_date=20231214T164352
[2023-12-14T16:43:52.108+0000] {standard_task_runner.py:104} ERROR - Failed to execute job 3 for task update_transaction_fact (update_transaction_fact() missing 1 required positional argument: 'records'; 78)
[2023-12-14T16:43:52.124+0000] {local_task_job_runner.py:228} INFO - Task exited with return code 1
[2023-12-14T16:43:52.145+0000] {taskinstance.py:2778} INFO - 0 downstream tasks scheduled from follow-on schedule check
[2023-12-14T16:56:28.178+0000] {taskinstance.py:1159} INFO - Dependencies all met for dep_context=non-requeueable deps ti=<TaskInstance: daily_transaction_fact.update_transaction_fact scheduled__2023-12-13T00:00:00+00:00 [queued]>
[2023-12-14T16:56:28.187+0000] {taskinstance.py:1159} INFO - Dependencies all met for dep_context=requeueable deps ti=<TaskInstance: daily_transaction_fact.update_transaction_fact scheduled__2023-12-13T00:00:00+00:00 [queued]>
[2023-12-14T16:56:28.187+0000] {taskinstance.py:1361} INFO - Starting attempt 1 of 2
[2023-12-14T16:56:28.198+0000] {taskinstance.py:1382} INFO - Executing <Task(PythonOperator): update_transaction_fact> on 2023-12-13 00:00:00+00:00
[2023-12-14T16:56:28.203+0000] {standard_task_runner.py:57} INFO - Started process 82 to run task
[2023-12-14T16:56:28.206+0000] {standard_task_runner.py:84} INFO - Running: ['***', 'tasks', 'run', 'daily_transaction_fact', 'update_transaction_fact', 'scheduled__2023-12-13T00:00:00+00:00', '--job-id', '4', '--raw', '--subdir', 'DAGS_FOLDER/transaction_fact.py', '--cfg-path', '/tmp/tmpj4p8cws_']
[2023-12-14T16:56:28.208+0000] {standard_task_runner.py:85} INFO - Job 4: Subtask update_transaction_fact
[2023-12-14T16:56:28.249+0000] {task_command.py:416} INFO - Running <TaskInstance: daily_transaction_fact.update_transaction_fact scheduled__2023-12-13T00:00:00+00:00 [running]> on host b650a3d4dd42
[2023-12-14T16:56:28.319+0000] {taskinstance.py:1662} INFO - Exporting env vars: AIRFLOW_CTX_DAG_OWNER='***' AIRFLOW_CTX_DAG_ID='daily_transaction_fact' AIRFLOW_CTX_TASK_ID='update_transaction_fact' AIRFLOW_CTX_EXECUTION_DATE='2023-12-13T00:00:00+00:00' AIRFLOW_CTX_TRY_NUMBER='1' AIRFLOW_CTX_DAG_RUN_ID='scheduled__2023-12-13T00:00:00+00:00'
[2023-12-14T16:56:28.321+0000] {taskinstance.py:1937} ERROR - Task failed with exception
Traceback (most recent call last):
  File "/home/airflow/.local/lib/python3.8/site-packages/airflow/operators/python.py", line 192, in execute
    return_value = self.execute_callable()
  File "/home/airflow/.local/lib/python3.8/site-packages/airflow/operators/python.py", line 209, in execute_callable
    return self.python_callable(*self.op_args, **self.op_kwargs)
TypeError: update_transaction_fact() missing 1 required positional argument: 'records'
[2023-12-14T16:56:28.330+0000] {taskinstance.py:1400} INFO - Marking task as UP_FOR_RETRY. dag_id=daily_transaction_fact, task_id=update_transaction_fact, execution_date=20231213T000000, start_date=20231214T165628, end_date=20231214T165628
[2023-12-14T16:56:28.340+0000] {standard_task_runner.py:104} ERROR - Failed to execute job 4 for task update_transaction_fact (update_transaction_fact() missing 1 required positional argument: 'records'; 82)
[2023-12-14T16:56:28.378+0000] {local_task_job_runner.py:228} INFO - Task exited with return code 1
[2023-12-14T16:56:28.396+0000] {taskinstance.py:2778} INFO - 0 downstream tasks scheduled from follow-on schedule check
[2023-12-14T17:01:24.506+0000] {taskinstance.py:1159} INFO - Dependencies all met for dep_context=non-requeueable deps ti=<TaskInstance: daily_transaction_fact.update_transaction_fact scheduled__2023-12-13T00:00:00+00:00 [queued]>
[2023-12-14T17:01:24.513+0000] {taskinstance.py:1159} INFO - Dependencies all met for dep_context=requeueable deps ti=<TaskInstance: daily_transaction_fact.update_transaction_fact scheduled__2023-12-13T00:00:00+00:00 [queued]>
[2023-12-14T17:01:24.513+0000] {taskinstance.py:1361} INFO - Starting attempt 1 of 2
[2023-12-14T17:01:24.522+0000] {taskinstance.py:1382} INFO - Executing <Task(PythonOperator): update_transaction_fact> on 2023-12-13 00:00:00+00:00
[2023-12-14T17:01:24.529+0000] {standard_task_runner.py:57} INFO - Started process 88 to run task
[2023-12-14T17:01:24.531+0000] {standard_task_runner.py:84} INFO - Running: ['***', 'tasks', 'run', 'daily_transaction_fact', 'update_transaction_fact', 'scheduled__2023-12-13T00:00:00+00:00', '--job-id', '3', '--raw', '--subdir', 'DAGS_FOLDER/transaction_fact.py', '--cfg-path', '/tmp/tmpubsgg6zr']
[2023-12-14T17:01:24.533+0000] {standard_task_runner.py:85} INFO - Job 3: Subtask update_transaction_fact
[2023-12-14T17:01:24.574+0000] {task_command.py:416} INFO - Running <TaskInstance: daily_transaction_fact.update_transaction_fact scheduled__2023-12-13T00:00:00+00:00 [running]> on host 2ec4e94e7d79
[2023-12-14T17:01:24.632+0000] {taskinstance.py:1662} INFO - Exporting env vars: AIRFLOW_CTX_DAG_OWNER='***' AIRFLOW_CTX_DAG_ID='daily_transaction_fact' AIRFLOW_CTX_TASK_ID='update_transaction_fact' AIRFLOW_CTX_EXECUTION_DATE='2023-12-13T00:00:00+00:00' AIRFLOW_CTX_TRY_NUMBER='1' AIRFLOW_CTX_DAG_RUN_ID='scheduled__2023-12-13T00:00:00+00:00'
[2023-12-14T17:01:24.633+0000] {taskinstance.py:1937} ERROR - Task failed with exception
Traceback (most recent call last):
  File "/home/airflow/.local/lib/python3.8/site-packages/airflow/operators/python.py", line 192, in execute
    return_value = self.execute_callable()
  File "/home/airflow/.local/lib/python3.8/site-packages/airflow/operators/python.py", line 209, in execute_callable
    return self.python_callable(*self.op_args, **self.op_kwargs)
TypeError: update_transaction_fact() missing 1 required positional argument: 'records'
[2023-12-14T17:01:24.640+0000] {taskinstance.py:1400} INFO - Marking task as UP_FOR_RETRY. dag_id=daily_transaction_fact, task_id=update_transaction_fact, execution_date=20231213T000000, start_date=20231214T170124, end_date=20231214T170124
[2023-12-14T17:01:24.650+0000] {standard_task_runner.py:104} ERROR - Failed to execute job 3 for task update_transaction_fact (update_transaction_fact() missing 1 required positional argument: 'records'; 88)
[2023-12-14T17:01:24.663+0000] {local_task_job_runner.py:228} INFO - Task exited with return code 1
[2023-12-14T17:01:24.676+0000] {taskinstance.py:2778} INFO - 0 downstream tasks scheduled from follow-on schedule check
[2023-12-14T17:10:12.493+0000] {taskinstance.py:1159} INFO - Dependencies all met for dep_context=non-requeueable deps ti=<TaskInstance: daily_transaction_fact.update_transaction_fact scheduled__2023-12-13T00:00:00+00:00 [queued]>
[2023-12-14T17:10:12.500+0000] {taskinstance.py:1159} INFO - Dependencies all met for dep_context=requeueable deps ti=<TaskInstance: daily_transaction_fact.update_transaction_fact scheduled__2023-12-13T00:00:00+00:00 [queued]>
[2023-12-14T17:10:12.500+0000] {taskinstance.py:1361} INFO - Starting attempt 1 of 2
[2023-12-14T17:10:12.509+0000] {taskinstance.py:1382} INFO - Executing <Task(PythonOperator): update_transaction_fact> on 2023-12-13 00:00:00+00:00
[2023-12-14T17:10:12.514+0000] {standard_task_runner.py:57} INFO - Started process 85 to run task
[2023-12-14T17:10:12.516+0000] {standard_task_runner.py:84} INFO - Running: ['***', 'tasks', 'run', 'daily_transaction_fact', 'update_transaction_fact', 'scheduled__2023-12-13T00:00:00+00:00', '--job-id', '3', '--raw', '--subdir', 'DAGS_FOLDER/transaction_fact.py', '--cfg-path', '/tmp/tmp0rygf8k3']
[2023-12-14T17:10:12.518+0000] {standard_task_runner.py:85} INFO - Job 3: Subtask update_transaction_fact
[2023-12-14T17:10:12.553+0000] {task_command.py:416} INFO - Running <TaskInstance: daily_transaction_fact.update_transaction_fact scheduled__2023-12-13T00:00:00+00:00 [running]> on host 7ea325c983f6
[2023-12-14T17:10:12.614+0000] {taskinstance.py:1662} INFO - Exporting env vars: AIRFLOW_CTX_DAG_OWNER='***' AIRFLOW_CTX_DAG_ID='daily_transaction_fact' AIRFLOW_CTX_TASK_ID='update_transaction_fact' AIRFLOW_CTX_EXECUTION_DATE='2023-12-13T00:00:00+00:00' AIRFLOW_CTX_TRY_NUMBER='1' AIRFLOW_CTX_DAG_RUN_ID='scheduled__2023-12-13T00:00:00+00:00'
[2023-12-14T17:10:12.616+0000] {taskinstance.py:1937} ERROR - Task failed with exception
Traceback (most recent call last):
  File "/home/airflow/.local/lib/python3.8/site-packages/airflow/operators/python.py", line 192, in execute
    return_value = self.execute_callable()
  File "/home/airflow/.local/lib/python3.8/site-packages/airflow/operators/python.py", line 209, in execute_callable
    return self.python_callable(*self.op_args, **self.op_kwargs)
TypeError: update_transaction_fact() missing 1 required positional argument: 'records'
[2023-12-14T17:10:12.623+0000] {taskinstance.py:1400} INFO - Marking task as UP_FOR_RETRY. dag_id=daily_transaction_fact, task_id=update_transaction_fact, execution_date=20231213T000000, start_date=20231214T171012, end_date=20231214T171012
[2023-12-14T17:10:12.632+0000] {standard_task_runner.py:104} ERROR - Failed to execute job 3 for task update_transaction_fact (update_transaction_fact() missing 1 required positional argument: 'records'; 85)
[2023-12-14T17:10:12.647+0000] {local_task_job_runner.py:228} INFO - Task exited with return code 1
[2023-12-14T17:10:12.664+0000] {taskinstance.py:2778} INFO - 0 downstream tasks scheduled from follow-on schedule check
[2023-12-14T17:16:26.118+0000] {taskinstance.py:1159} INFO - Dependencies all met for dep_context=non-requeueable deps ti=<TaskInstance: daily_transaction_fact.update_transaction_fact scheduled__2023-12-13T00:00:00+00:00 [queued]>
[2023-12-14T17:16:26.124+0000] {taskinstance.py:1159} INFO - Dependencies all met for dep_context=requeueable deps ti=<TaskInstance: daily_transaction_fact.update_transaction_fact scheduled__2023-12-13T00:00:00+00:00 [queued]>
[2023-12-14T17:16:26.124+0000] {taskinstance.py:1361} INFO - Starting attempt 1 of 2
[2023-12-14T17:16:26.133+0000] {taskinstance.py:1382} INFO - Executing <Task(PythonOperator): update_transaction_fact> on 2023-12-13 00:00:00+00:00
[2023-12-14T17:16:26.138+0000] {standard_task_runner.py:57} INFO - Started process 105 to run task
[2023-12-14T17:16:26.140+0000] {standard_task_runner.py:84} INFO - Running: ['***', 'tasks', 'run', 'daily_transaction_fact', 'update_transaction_fact', 'scheduled__2023-12-13T00:00:00+00:00', '--job-id', '3', '--raw', '--subdir', 'DAGS_FOLDER/transaction_fact.py', '--cfg-path', '/tmp/tmpeidct7ae']
[2023-12-14T17:16:26.142+0000] {standard_task_runner.py:85} INFO - Job 3: Subtask update_transaction_fact
[2023-12-14T17:16:26.177+0000] {task_command.py:416} INFO - Running <TaskInstance: daily_transaction_fact.update_transaction_fact scheduled__2023-12-13T00:00:00+00:00 [running]> on host 3d6ae99c9c0c
[2023-12-14T17:16:26.236+0000] {taskinstance.py:1662} INFO - Exporting env vars: AIRFLOW_CTX_DAG_OWNER='***' AIRFLOW_CTX_DAG_ID='daily_transaction_fact' AIRFLOW_CTX_TASK_ID='update_transaction_fact' AIRFLOW_CTX_EXECUTION_DATE='2023-12-13T00:00:00+00:00' AIRFLOW_CTX_TRY_NUMBER='1' AIRFLOW_CTX_DAG_RUN_ID='scheduled__2023-12-13T00:00:00+00:00'
[2023-12-14T17:16:26.238+0000] {taskinstance.py:1937} ERROR - Task failed with exception
Traceback (most recent call last):
  File "/home/airflow/.local/lib/python3.8/site-packages/airflow/operators/python.py", line 192, in execute
    return_value = self.execute_callable()
  File "/home/airflow/.local/lib/python3.8/site-packages/airflow/operators/python.py", line 209, in execute_callable
    return self.python_callable(*self.op_args, **self.op_kwargs)
TypeError: update_transaction_fact() missing 1 required positional argument: 'records'
[2023-12-14T17:16:26.245+0000] {taskinstance.py:1400} INFO - Marking task as UP_FOR_RETRY. dag_id=daily_transaction_fact, task_id=update_transaction_fact, execution_date=20231213T000000, start_date=20231214T171626, end_date=20231214T171626
[2023-12-14T17:16:26.256+0000] {standard_task_runner.py:104} ERROR - Failed to execute job 3 for task update_transaction_fact (update_transaction_fact() missing 1 required positional argument: 'records'; 105)
[2023-12-14T17:16:26.272+0000] {local_task_job_runner.py:228} INFO - Task exited with return code 1
[2023-12-14T17:16:26.291+0000] {taskinstance.py:2778} INFO - 0 downstream tasks scheduled from follow-on schedule check
